Workbook

Sheet 101
A1: Linha 101 - Gralha Azul - Pq. Ind. - UTFPR - UNIDEP
A2: (Bairro Gralha Azul) Rua Jaury Heitor de Souza, Rua Ricieri Pastori, Rua Marcelino Parzianello, Rua das Flores, Marginal Av. Tupi, Av. Tupi, Av. Tupi, Av. Brasil, Rua Xingú, Rua Tamoio, P I 3, Rua Ararigboia, Rua Tocantins, P I 4, Rua Jaciretã, Av. Tupi, Trevo do Patinho, BR-158, CAPEG, (# Granja Real, Parque Industrial Theóphilo Petrikoski), BR-158, PR 493, UTFPR, Rua Eliza Cola Padoan, Rua Irineu Parzianello, Rua Lidio Oltramari, Rua Benjamim Borges dos Santos, UNIDEP, PR 493,Trevo Patinho, Av. Tupi, Rua Tapir, Rua Caramuru, P I 1, Rua Tamoio, Av. Tupi, Marginal Av. Tupi, Rua das Flores, Rua Princesa Isabel, Rua Jaury Heitor de Souza (Bairro Gralha Azul).
A3: SEGUNDA-FEIRA À SEXTA-FEIRA (SÁBADO ATÉ AS 13H20MIN)
A4: Bairro Gralha Azul | B4: P I 3 Ponto Antiga Rodoviária (Rua Tamoio) | C4: #GRANJA REAL | D4: UTFPR - UNIDEP | E4: P I 1 Ponto Casa do Artesão (Rua Caramuru)
A5: / | B5: / | C5: / | D5: / | E5: 0.22222222
A6: / | B6: / | C6: / | D6: / | E6: 0.25
A7: 0.23263889 | B7: 0.25 | C7: 0.25694444 | D7: 0.26388889 | E7: 0.27777778
A8: 0.26041667 | B8: 0.27777778 | C8: 0.28819444 | D8: 0.29166667 | E8: 0.30555556
A9: 0.28819444 | B9: 0.30555556 | C9: / | D9: 0.31944444 | E9: 0.33333333
A10: 0.31597222 | B10: 0.33333333 | C10: / | D10: 0.34722222 | E10: 0.36111111
A11: 0.34375 | B11: 0.36111111 | C11: / | D11: 0.375 | E11: 0.38888889
A12: 0.37152778 | B12: 0.38888889 | C12: / | D12: 0.40277778 | E12: 0.41666667
A13: 0.39930556 | B13: 0.41666667 | C13: / | D13: 0.43055556 | E13: 0.44444444
A14: 0.42708333 | B14: 0.44444444 | C14: / | D14: 0.45833333 | E14: 0.47222222
A15: 0.45486111 | B15: 0.47222222 | C15: 0.47916667 | D15: 0.48611111 | E15: 0.5
A16: 0.48263889 | B16: 0.5 | C16: / | D16: 0.51388889 | E16: 0.52777778
A17: 0.51041667 | B17: 0.52777778 | C17: / | D17: 0.54166667 | E17: 0.55555556
A18: 0.53819444 | B18: 0.55555556 | C18: / | D18: 0.56944444 | E18: 0.58333333
A19: 0.56597222 | B19: 0.58333333 | C19: / | D19: 0.59722222 | E19: 0.61111111
A20: 0.59375 | B20: 0.61111111 | C20: / | D20: 0.625 | E20: 0.63888889
A21: 0.62152778 | B21: 0.63888889 | C21: / | D21: 0.65277778 | E21: 0.66666667
A22: 0.64930556 | B22: 0.66666667 | C22: / | D22: 0.68055556 | E22: 0.69444444
A23: 0.67708333 | B23: 0.69444444 | C23: / | D23: 0.70833333 | E23: 0.72222222
A24: 0.70486111 | B24: 0.72222222 | C24: / | D24: 0.73611111 | E24: 0.75
A25: 0.73263889 | B25: 0.75 | C25: 0.75694444 | D25: 0.76388889 | E25: 0.77777778
A26: 0.76041667 | B26: 0.77777778 | C26: / | D26: 0.79166667 | E26: 0.80555556
A27: 0.78819444 | B27: 0.80555556 | C27: / | D27: 0.81944444 | E27: 0.83333333
A28: 0.81597222 | B28: 0.83333333 | C28: / | D28: 0.84722222 | E28: 0.86111111
A29: 0.84375 | B29: 0.86111111 | C29: / | D29: 0.875 | E29: 0.88888889
A30: 0.87152778 | B30: 0.88888889 | C30: / | D30: 0.90277778 | E30: 0.91666667
A31: 0.90277778 | B31: 0.91666667 | C31: / | D31: 0.93055556 | E31: 0.94444444
A32: 0.92708333 | B32: 0.94444444 | C32: / | D32: 0.96180556 | E32: 0.97222222
A33: 0.95486111 | B33: 0.97222222
A34: 0.98263889 | B34: 0 | C34: / | D34: / | E34: /
A36: Linha 101 - Gralha Azul - Pq. Ind. - UTFPR - UNIDEP
A37: (Bairro Gralha Azul) Rua Jaury Heitor de Souza, Rua Ricieri Pastori, Rua Marcelino Parzianello, Rua das Flores, Marginal Av. Tupi, Av. Tupi, Av. Brasil, Rua Xingú, Rua Tamoio, P I 3, Rua Ararigboia, Rua Tocantins, P I 4, Rua Jaciretã, Avenida Tupi, Trevo do Patinho, BR 158, Parque Industrial Theophilo Petrikoski, (# Granja Real, Parque Industrial Theóphilo Petrikoski) BR 158, PR 493, UTFPR, Rua Eliza Cola Padoan, Rua Irineu Parzianello, Rua Lidio Oltramari, Rua Benjamim Borges dos Santos, UNIDEP, PR 493,Trevo Patinho, Av. Tupi, Avenida da Inovação (Shopping Pato Branco) Avenida da Inovação, Avenida Tupi, Trevo do Patinho, Avenida Tupi, Rua Tapir, Rua Caramuru, P I 1, Rua Tamoio, Av. Tupi, Marginal Av. Tupi, Rua das Flores, Rua Princesa Isabel, Rua Jaury Heitor de Souza (Bairro Gralha Azul).
A38: SÁBADO
A39: Bairro Gralha Azul | B39: P I 3 Ponto Antiga Rodoviária (Rua Tamoio) | C39: # Granja Real - Bairro São Francisco | D39: UTFPR - UNIDEP | E39: Shopping Pato Branco | F39: P I 1 Ponto Casa do Artesão (Rua Caramuru)
D40: 0.625 | E40: 0.63194444 | F40: 0.63888889
C41: / | D41: 0.65277778 | E41: 0.65972222 | F41: 0.66666667
...

Sheet 102
A1: Linha 102 - Av. Tupi - UTFPR - UNIDEP
A2: (Bairro Encruzilhada) Trevo Patrola, Marginal Av. Tupi, Av. Tupi, Av. Brasil, Rua Xingú, Rua Tamoio, P I 3, Rua Ararigboia, Rua Tocantins, P I 4, Rua Jaciretã, Av. Tupi, Trevo do Patinho, BR 158, Parque Industrial Theophilo Petrikosi, BR 158 PR-493, (# BR-158, Granja Real, BR 158), PR 493, UTFPR, Rua Eliza Cola Padoan, Rua Irineu Parzianello, Rua Lidio Oltramari, Rua Benjamim Borges dos Santos, UNIDEP, PR-493, Trevo Patinho, Av. Tupi, Rua Tapir, Rua Caramuru, P I 1, Rua Tamoio, Av. Tupi, Marginal Av. Tupi, Av. Tupi, Trevo da Patrola (Bairro Encruzinhada).
A3: SEGUNDA-FEIRA À SEXTA-FEIRA
A4: Trevo Patrola | B4: Bairro Planalto (Rua Siriemas) | C4: P I 3 Ponto Casa do Artesão (Rua Tamoio) | D4: # Granja Real | E4: Shopping Pato Branco | F4: UTFPR - UNIDEP | G4: P I 1 Ponto Casa do Artesão (Rua Caramuru)
A5: / | B5: / | C5: / | D5: / | E5: / | F5: 0.22222222 | G5: 0.23611111
A6: / | B6: / | C6: 0.23611111 | D6: / | E6: / | F6: 0.25 | G6: 0.26388889
A7: 0.25 | B7: / | C7: 0.26388889 | D7: / | E7: / | F7: 0.27777778 | G7: 0.29166667
A8: 0.26041667 | B8: / | C8: 0.27430556 | D8: / | E8: / | F8: 0.28819444 | G8: /
A9: 0.27777778 | B9: / | C9: 0.29166667 | D9: 0.30208333 | E9: / | F9: 0.30555556 | G9: 0.31944444
A10: 0.28819444 | B10: / | C10: 0.30208333 | D10: / | E10: / | F10: 0.31597222 | G10: /
A11: 0.30555556 | B11: / | C11: 0.31944444 | D11: / | E11: / | F11: 0.33333333 | G11: 0.34722222
A12: 0.33333333 | B12: / | C12: 0.34722222 | D12: / | E12: / | F12: 0.36111111 | G12: 0.375
A13: 0.36111111 | B13: / | C13: 0.375 | D13: / | E13: / | F13: 0.38888889 | G13: 0.40277778
A14: 0.38888889 | B14: / | C14: 0.40277778 | D14: / | E14: / | F14: 0.41666667 | G14: 0.43055556
A15: 0.41666667 | B15: / | C15: 0.43055556 | D15: / | E15: / | F15: 0.44444444 | G15: 0.45833333
A16: 0.44444444 | B16: / | C16: 0.45833333 | D16: / | E16: / | F16: 0.47222222 | G16: 0.48611111
A17: 0.47222222 | B17: / | C17: 0.48611111 | D17: / | E17: / | F17: 0.5 | G17: 0.51388889
A18: 0.5 | B18: / | C18: 0.51388889 | D18: / | E18: / | F18: 0.52777778 | G18: 0.54166667
A19: 0.52777778 | B19: / | C19: 0.54166667 | D19: / | E19: / | F19: 0.55555556 | G19: 0.56944444
A20: 0.55555556 | B20: / | C20: 0.56944444 | D20: / | E20: / | F20: 0.58333333 | G20: 0.59722222
A21: 0.58333333 | B21: / | C21: 0.59722222 | D21: / | E21: / | F21: 0.61111111 | G21: 0.625
A22: 0.61111111 | B22: / | C22: 0.625 | D22: / | E22: / | F22: 0.63888889 | G22: 0.65277778
... A25: 0.69444444 | B25: / | C25: 0.70833333 | D25: / | E25: / | F25: 0.72222222 | G25: 0.73611111
A26: / | B26: / | C26: / | D26: / | E26: / | F26: 0.71875 | G26: 0.73263889
A27: 0.74652778 | B27: / | C27: / | D27: / | E27: / | F27: / | G27: /
A28: 0.72222222 | B28: / | C28: 0.73611111 | D28: 0.74652778 | E28: / | F28: 0.75 | G28: 0.76388889
A29: / | B29: / | C29: / | D29: / | E29: / | F29: 0.73263889 | G29: 0.74652778
A30: 0.76041667 | B30: / | C30: 0.77430556 | D30: / | E30: / | F30: 0.79513889 | G30: /
A31: 0.75 | B31: / | C31: 0.76388889 | D31: / | E31: / | F31: 0.77777778 | G31: 0.79166667
A32: 0.77777778 | B32: / | C32: 0.79166667 | D32: / | E32: / | F32: 0.80555556 | G32: 0.81944444
A33: 0.80555556 | B33: / | C33: 0.81944444 | D33: / | E33: / | F33: 0.83333333 | G33: 0.84722222
A34: 0.83333333 | B34: / | C34: 0.84722222 | D34: / | E34: / | F34: / | G34: /
A35: 0.86111111 | B35: / | C35: 0.875 | D35: / | E35: / | F35: 0.88888889 | G35: 0.90277778
A36: 0.91666667 | B36: / | C36: 0.93055556 | D36: / | E36: 0.9375 | F36: 0.94791667 | G36: 0.96180556
A37: 0.97569444 | B37: 0.98263889 | C37: / | D37: / | E37: / | F37: / | G37: /
A39: Linha 102 - Av. Tupi - UTFPR - UNIDEP
A40: (Bairro Gralha Azul) Rua Jaury Heitor de Souza, Rua Ricieri Pastori, Rua Marcelino Parzianello, Rua das Flores, Marginal Av. Tupi, (Trevo Patrola), Marginal Av. Tupi, Av. Tupi, Av. Brasil, Rua Xingú, Rua Tamoio, P I 3, Rua Ararigboia, Rua Tocantins, P I 4, Rua Jaciretã, Av. Tupi, (Avenida da Inovação (Shopping Pato Branco) Avenida da Inovação), Trevo do Patinho, BR 158, Parque Industrial Teophilo Petrikoski, BR 158, PR-493, UTFPR, Rua Eliza Cola Padoan, Rua Irineu Parzianello, Rua Lidio Oltramari, Rua Benjamim Borges dos Santos, UNIDEP, PR-493, Trevo Patinho, Av. Tupi, (Avenida da Inocavação (Shopping Pato Branco), Avenida da Inovação, Avenida Tupi, Rua Tapir, Rua Caramuru, P I 1, Rua Tamoio, Av. Tupi, Rua Uruguaiana, Rua Marechal Deodoro, Rua General Osório, Rua Tiradentes, Rua Princesa Isabel, Rua Alexandre Gusmão, Av. Tupi, Trevo da Patrola.
A41: DOMINGOS
A42: Trevo Patrola | B42: Gralha Azul | C42: P I 3 Ponto Casa do Artesão (Rua Tamoio) | D42: Shopping Pato Branco | E42: UTFPR - UNIDEP | F42: Shopping Pato Branco | G42: P I 1 Ponto Casa do Artesão (Rua Caramuru)
F43: 0.28819444 | G43: 0.29513889
...

Sheet 103
A1: Linha 103 - Gralha Azul - Centro (via Alvorada)
A2: (Bairro Gralha Azul) Rua Jaury Heitor de Souza, Rua Riciere Pastori, Rua Marcelino Parzianello, Rua Princesa Isabel (Bairro Alvorada, Bairro Santo Antônio), Rua Tiradentes, Rua General Ozorio, Rua Marechal Deodoro, Rua Uruguaiana, Av. Tupi, Av. Brasil, Rua Xingú, Rua Tamoio, P I 2, Rua Ararigboia, Rua Tocantins, P I 4, Rua Jaciretã, Av. Tupi, Rua Tapir, Rua Caramuru, P I 1, Rua Tamoio, Av. Tupi, Rua Uruguaiana, Rua Marechal Deodoro, Rua General Ozorio, Rua Tiradentes, Rua Princesa Isabel (Bairro Santo Antônio, Bairro Alvorada), Rua Jaury Heitor de Souza (Bairro Gralha Azul).
A3: SEGUNDA-FEIRA À SEXTA
A4: Bairro Gralha Azul | B4: P I 2 Ponto Casa do Artesão (Rua Tamoio) | C4: Ponto Rua Tapir | D4: P I 1 Ponto Casa do Artesão (Rua Caramuru)
A5: / | B5: / | C5: / | D5: 0.23263889
A6: / | B6: / | C6: / | D6: 0.25347222
A7: 0.24652778 | B7: 0.26041667 | C7: 0.26388889 | D7: 0.26736111
A8: 0.26736111 | B8: 0.28125 | C8: 0.28472222 | D8: 0.28819444
A9: 0.28125 | B9: 0.29513889 | C9: 0.29861111 | D9: 0.30208333
A10: 0.30208333 | B10: 0.31597222 | C10: 0.31944444 | D10: 0.32291667
A11: 0.31597222 | B11: 0.32986111 | C11: 0.33333333 | D11: 0.33680556
A12: 0.33680556 | B12: 0.35069444 | C12: 0.35416667 | D12: 0.35763889
A13: 0.35069444 | B13: 0.36458333 | C13: 0.36805556 | D13: /
A14: 0.37152778 | B14: 0.38541667 | C14: / | D14: /
A15: / | B15: / | C15: / | D15: /
A16: / | B16: / | C16: 0.45833333 | D16: 0.46180556
A17: / | B17: / | C17: 0.47222222 | D17: 0.47569444
A18: 0.47569444 | B18: 0.48958333 | C18: 0.49652778 | D18: 0.5
A19: 0.48958333 | B19: 0.50347222 | C19: 0.50694444 | D19: 0.51041667
A20: 0.51388889 | B20: 0.52430556 | C20: 0.52777778 | D20: 0.53125
A21: 0.52430556 | B21: 0.53819444 | C21: 0.54166667 | D21: 0.54513889
A22: 0.54513889 | B22: 0.55902778 | C22: 0.5625 | D22: /
A23: 0.55902778 | B23: 0.57291667 | C23: 0.57638889 | D23: /
A24: 0.57986111 | B24: 0.59375 | C24: / | D24: /
A25: / | B25: / | C25: / | D25: /
A26: / | B26: / | C26: 0.66666667 | D26: 0.67013889
A27: / | B27: / | C27: 0.68055556 | D27: 0.68402778
A28: 0.68402778 | B28: 0.69791667 | C28: 0.70138889 | D28: 0.70486111
A29: 0.69791667 | B29: 0.71180556 | C29: 0.71527778 | D29: 0.71875
A30: 0.71875 | B30: 0.73263889 | C30: 0.73611111 | D30: 0.73958333
A31: 0.73263889 | B31: 0.74652778 | C31: 0.75 | D31: 0.75347222
A32: 0.75347222 | B32: 0.76736111 | C32: 0.77083333 | D32: 0.77430556
A33: 0.76736111 | B33: 0.78125 | C33: 0.78472222 | D33: 0.78819444
A34: 0.78819444 | B34: 0.80208333 | C34: 0.80555556 | D34: 0.80902778
A35: 0.80902778 | B35: 0.81597222 | C35: 0.81944444 | D35: /
A36: 0.82986111 | B36: 0.84375 | C36: 0.84722222 | D36: 0.85069444
A37: 0.87152778 | B37: 0.88541667 | C37: / | D37: /
A39: SÁBADOS
A40: (Bairro Alvorada) Rua Princesa Isabel, Rua Tiradentes, Rua General Ozório, Rua Marechal Deodoro, Rua Curitiba, Rua dos Jasmins, Rua Bento Gonçalves, Rua Marechal Deodoro, Rua Uruguaiana, Av. Tupi, Av. Brasil, Rua Xingú, Rua Tamoio, P I 2, Rua Ararigbóia, Rua Tocantins, P I 4, Rua Jaciretã, Av. Tupi, Rua Tapir, Rua Caramuru, P I 1, Rua Tamoio, Av. Tupi, Rua Uruguaiana, Rua Marechal Deodoro, Rua General Ozório, Rua Tiradentes, Rua Princesa Isabel (Bairro Santo Antônio), Rua Osvaldo Cruz, Travessa Ipacaraí, Rua Castelo Branco (Bairro Alvorada).
A41: Bairro Alvorada | B41: P I 2 Ponto Casa do Artesão (Rua Tamoio) | C41: Ponto Rua Tapir | D41: P I 1 Ponto Casa do Artesão (Rua Caramuru)
...

Sheet 105
A1: Linha 105 - La Salle / Vila Isabel
A2: Rua Tapir, Rua Caramuru, Rua Tamoio, P I 2, Rua Ararigboia, (Bairro La Salle - Ponto em frente à TV), Rua Frei Sérgio Hillescheim, Rua Lídio Guerra, Rua André Borsoi, Rua Pioneiro Alberto Braun, Rua Itapuã, Rua Itacolomi, Rua Tocantins, P I 4, Rua Tocantins, Rua Itabira, Rua José Vergílio Cantu, Rua Tapir, Rua José Cattani, Rua Manoel Ribas, Rua Sílva Jardim, Av. das Torres, Rua Abel Bortot, Rua Tocantins, Rua Oswaldo Aranha, Avenida Tupi, Rua Tapir
A3: SEGUNDA-FEIRA À SEXTA-FEIRA
A4: Ponto Rua Tapir | B4: P I 2 Ponto Casa do Artesão (Rua Tamoio | C4: Bairro La Salle | D4: P I 4 Ponto Pavilhão São Pedro | E4: Bairro Cadorin (Irmãs Teatinas)
B5: 0.25347222 | C5: 0.26041667 | D5: 0.26736111 | E5: 0.27430556
A6: 0.28125 | B6: 0.28472222 | C6: 0.29166667 | D6: 0.29861111 | E6: 0.30555556
A7: 0.3125 | B7: 0.31597222 | C7: 0.32291667 | D7: 0.32986111 | E7: 0.33680556
A8: 0.34375 | B8: 0.34722222
A9: 0.5 | B9: 0.50347222 | C9: 0.51041667 | D9: 0.51736111 | E9: 0.52430556
A10: 0.53125 | B10: 0.53472222 | C10: 0.54166667 | D10: 0.54861111 | E10: 0.55555556
A11: 0.5625 | B11: 0.56597222
A12: 0.66319444 | B12: 0.66666667 | C12: 0.67361111 | D12: 0.68055556 | E12: 0.6875
A13: 0.69444444 | B13: 0.69791667 | C13: 0.70486111 | D13: 0.71180556 | E13: 0.71875
A14: 0.72569444 | B14: 0.72916667 | C14: 0.73611111 | D14: 0.74305556 | E14: 0.75
A15: 0.75694444 | B15: 0.76041667 | C15: 0.76736111 | D15: 0.77430556 | E15: 0.78125
A16: 0.78819444
A18: Exceções
A20: SÁBADOS
A21: 1. É executado até a viagem das 12h45min.

Sheet 107
A1: Linha 107 - Veneza - UTFPR
A2: Rua Ângelo Gabriel, Rua dos Gerânios, Rua Curitiba, Rua dos Jasmins, Rua Jaci R Ferreira (Bairro Novo Horizonte), Rua Bento Gonçalves, Rua das Hortênsias, Rua Antonio Ascari (Bairro Cristo Rei), Av. Tupi, Av. Brasil, Rua Xingú, Rua Tamoio, P I 3 (Antiga Rodoviária), Rua Ararigboia, Rua Tocantins, P I 4, Rua Jaciretã, Av. Tupi, Trevo Patinho,BR 158 Parque Industrial Teophilo Petrikoski, BR 158, PR-493, UTFPR, Rua Eliza Cola Padoan, Rua Irineu Parzianello, Rua Lidio Oltramari, Rua Benjamim Borges dos Santos, UNIDEP, PR-493, Trevo Patinho, Av. Tupi, Rua Tapir, Rua Caramuru, P I 1, Rua Tamoio, Av. Tupi, Rua Uruguaiana, Rua Marechal Deodoro, Rua Curitiba, Rua Ângelo Gabriel.
A3: SEGUNDA-FEIRA À SEXTA-FEIRA
A4: Bairro Veneza | B4: P I 3 Ponto Antiga Rodoviária (Rua Tamoio) | C4: UTFPR - UNIDEP | D4: Trevo Patinho ( Três Cantos) | E4: P I 1 Ponto Casa do Artesão (Rua Caramuru)
A5: / | B5: / | C5: / | E5: 0.23611111
A6: / | B6: / | C6: / | E6: 0.25
A7: 0.24652778 | B7: 0.25694444 | C7: 0.26736111 | E7: 0.27777778
A8: 0.25694444 | B8: 0.26736111 | C8: 0.27777778 | E8: 0.28819444
A9: 0.28819444 | B9: 0.29861111 | C9: 0.3125 | E9: 0.32291667
A10: 0.30555556 | B10: 0.31597222 | C10: 0.32986111 | E10: 0.34027778
A11: 0.33333333 | B11: 0.34722222 | C11: 0.36111111 | E11: 0.37152778
A12: 0.35069444 | B12: 0.36458333 | C12: 0.37847222 | E12: /
A13: 0.38541667 | B13: 0.39930556 | C13: 0.40972222 | E13: 0.42361111
A14: / | B14: / | C14: / | E14: 0.44444444
A15: 0.4375 | B15: 0.45138889 | C15: 0.46527778 | E15: 0.47916667
A16: 0.45486111 | B16: 0.46875 | C16: 0.48263889 | E16: 0.5
A17: 0.48958333 | B17: 0.50347222 | C17: 0.51736111 | E17: 0.53125
A18: 0.51041667 | B18: 0.52083333 | C18: 0.53472222 | E18: 0.54861111
A19: 0.54166667 | B19: 0.55555556 | C19: 0.56944444 | E19: 0.58333333
A20: 0.55902778 | B20: 0.57291667 | C20: 0.58680556 | E20: 0.60069444
A21: 0.59375 | B21: 0.60763889 | C21: 0.62152778 | E21: 0.63541667
A22: 0.61111111 | B22: 0.625 | C22: 0.63888889 | E22: 0.65277778
A23: 0.64583333 | B23: 0.65972222 | C23: 0.67361111 | E23: 0.6875
A24: 0.66666667 | B24: 0.68055556 | C24: 0.69444444 | E24: 0.70833333
A25: 0.69791667 | B25: 0.71180556 | C25: 0.72569444 | E25: 0.73958333
A26: 0.72222222 | B26: 0.73611111 | C26: 0.75 | E26: 0.76388889
A27: / | B27: / | C27: / | D27: 0.74305556 | E27: 0.76041667
A28: 0.77083333 | B28: 0.78472222
A29: 0.75 | B29: 0.76388889 | C29: 0.77777778 | E29: 0.79166667
A30: 0.77430556 | B30: 0.78819444 | C30: 0.80208333 | E30: 0.81597222
A31: 0.80208333 | B31: 0.81597222 | C31: 0.82986111 | E31: /
A32: 0.82638889 | B32: 0.84027778 | C32: / | E32: /
C33: 0.96180556 | E33: 0.97569444
A34: 0.98611111 | B34: 0
A36: Exceções
A37: Segunda à sexta-feira
A38: 1. O Carro 03 às 17h50min é executado de segunda-feira à sexta-feira com o seguinte itinerário: Três Cantos, PR 493, Trevo do Patinho, Av. Tupi, Rua Tapir, Rua Caramuru, P I 1, Rua Tamoio, Av. Tupi, Rua Uruguaiana, Rua Marechal Deodoro, Rua Curitiba, Rua Ângelo Gabriel, Rua dos Gerânios, Rua Curitiba, Rua dos Jasmins, Rua Bento Gonçalves, Rua das Violetas, Rua Uruguaiana, Rua Fernando Ferrari, Rua Anchieta, Rua Fernando Ferrari, Rua Dr. Beltrão, Avenida Tupi, Avenida Brasil, Rua Xingu, Rua Tamoio PI3.
A39: Sábados
A40: 1. Para nas viagens das 14h00min e 14h05min.
A41: 2. A partir das 16h00min o atendimento é realizado pela Linha 103.
...

Sheet 108
A1: Linha 108 - Gralha Azul - Centro (via Bonato)
A2: (Bairro Gralha Azul), Rua Princesa Isabel, Rua Eduardo Dagios, Rua Jandir Peruzzo, Rua Jaury Heitor de Souza, Rua Ricieri Pastori, Rua Marcelino Parzianello, Rua Princesa Isabel, (Bairro Alvorada, Bairro Santo Antônio), Rua Gonçalves Dias, (Bairro Sudoeste), Rua Itá, Rua Tiradentes, Rua Ivá, Rua São José, Rua Curitiba, (Bairro Veneza, Bairro Novo Horizonte), Rua das Violetas, Rua Angelo Dal Bosco, Rua Fernando Ferrari, (Bairro Bonatto), Rua Anchieta, Rua Fernando Ferrari, Rua Industrial, Rua Santa Fé, Rua Dr. Francisco Beltrão, (Bairro Industrial), Rua Tocantins, Rua Itacolomi, Rua Tamoio, P I 2, Rua Ararigboia, Rua Tocantins, P I 4, Rua Iguaçu, Rua Aimoré, Rua Itacolomi, Rua Tocantins, Rua Dr. Francisco Beltrão, (Bairro Industrial), Rua Santa Fé, Rua Industrial, Rua Fernando Ferrari, Rua Anchieta, Rua Fernando Ferrari, (Bairro Bonatto), Rua Angelo Dal Bosco, Rua das Violetas (Bairro Veneza, Bairro Novo Horizonte), Rua Curitiba, Rua São José, Rua Ivá (Bairro Sudoeste Bairro Santo Antônio), Rua Tiradentes, Rua Itá, Rua Gonçalves Dias, Rua Princesa Isabel, (Bairro Alvorada), Rua Eduardo Dagios, (Bairro Gralha Azul).
A3: SEGUNDA-FEIRA À SEXTA
A4: Bairro Gralha Azul | C4: P I 2 Ponto Casa do Artesão (Rua Tamoio)
A5: 0.26388889 | C5: 0.28472222
A6: 0.30555556 | C6: 0.32638889
A7: 0.34722222 | C7: 0.36805556
A8: / | C8: 0.45138889
A9: 0.47222222 | C9: 0.5
A10: 0.54166667 | C10: 0.5625
A11: / | C11: 0.6875
A12: 0.70833333 | C12: 0.73263889
A13: 0.75 | C13: 0.77083333
A15: Exceções
A17: Segunda-feira à Sexta-feira
A18: 1. No itinerário das 07h50min, 12h00min e 16h30min no sentido PI2 (Casa do Artesão) - Bairro Gralha Azul inclui-se ao intinerário a Rua Sebastião Lara, Rua Altamira e Rua Antônio Pedro Ferronaro.
A19: 1. No itinerário das 08h20min, 13h00min e 17h00min no sentido Bairro Gralha Azul - PI2 (Casa do Artesão) inclui-se ao intinerário a Rua Antônio Pedro Ferronaro, Rua Altamira e Sebastião Lara.
A21: SÁBADOS
A22: 1. É executado até às 13h30min.

Sheet 109
A2: Linha 109 - Passo da Pedra
A3: P I 3, Rua Tamoio, Rua Ararigbóia, Rua Tocantins, P I 4, Rua Jaciretã, Av. Tupi, Trevo Patinho, PR-493, Bairro Passo da Pedra, PR-493, Trevo Patinho, Av. Tupi, Rua Tapir, Rua Caramuru, Rua Itacolomi, Rua Tamoio, P I 3.
A4: SEGUNDA-FEIRA À SEXTA-FEIRA
A5: P I 3 Ponto Antiga Rodoviária | B5: P I 4 Ponto Pavilhão São Pedro | C5: VIBRA | D5: Passo da Pedra | E5: VIBRA | F5: Trevo do Patinho (Três Cantos)
A6: / | B6: / | C6: / | D6: 0.27777778 | E6: / | F6: /
A7: 0.29166667 | B7: 0.29513889 | C7: 0.30902778 | D7: 0.31944444 | E7: / | F7: /
A8: 0.34027778 | B8: 0.34375 | C8: / | D8: 0.36111111 | E8: 0.36805556 | F8: /
A9: 0.38194444 | B9: / | C9: / | D9: / | E9: / | F9: /
A10: 0.47916667 | B10: 0.48263889 | C10: 0.49652778 | D10: 0.5 | E10: / | F10: /
A11: 0.52083333 | B11: 0.52430556 | C11: / | D11: 0.53819444 | E11: 0.54166667 | F11: /
A12: 0.5625 | B12: 0.56597222 | C12: / | D12: 0.58333333 | E12: 0.58680556 | F12: /
A13: 0.60416667 | B13: / | C13: / | D13: / | E13: / | F13: /
A14: 0.71875 | B14: 0.72222222 | C14: / | D14: 0.72916667 | E14: 0.73958333 | F14: 0.74305556

Sheet 110
A1: Linha 110 - São Cristovão - Rodoviária
A2: (Bairro São Cristóvão), Marginal Av. Tupi, Rua Alexandre Gusmão, Rua da Inconfidência, Rua Luiz Xavier, Rua Manoel Bandeira, Rua Vinte e Um de Abril, Rua Érico Verissimo, Rua Papa João XXIII, Rua Manoel Bandeira, Rua Antônio Garcês, Rua R. da República, Av. Tupi, Av. Brasil, Rua Xingu, Rua Tamoio, PI 2, Rua Iguaçu, Rua Guarani, Rua Farrapos, Av. Brasil (Ponto Rodoviária), Trevo Taísa, Rua Nereu Ramos, Rua Caramuru, P I 1, Av. Tupi, Marginal da Av. Tupi, (Bairro São Cristóvão).
A3: SEGUNDA-FEIRA À SEXTA-FEIRA
A4: Bairro São Cristovão | B4: P I 2 Ponto Casa do Artesão (Rua Tamoio) | C4: Ponto Rodoviária | D4: P I 1 Ponto Casa do Artesão (Rua Caramuru)
A5: / | B5: / | C5: 0.25 | D5: 0.25694444 | E5: 05 MIN A MAIS DO BAIRRO / CENTRO A PARTIR 2025
A6: 0.26736111 | B6: 0.28472222 | C6: 0.29166667 | D6: 0.29861111
A7: 0.30902778 | B7: 0.32638889 | C7: 0.33333333 | D7: 0.34027778
A8: 0.35069444 | B8: 0.36805556 | C8: 0.375 | D8: 0.38194444
A9: 0.39236111 | B9: 0.40972222 | C9: 0.41666667 | D9: 0.42361111
A10: 0.43402778 | B10: 0.45138889 | C10: 0.45833333 | D10: 0.46527778
A11: 0.47569444 | B11: 0.49305556 | C11: 0.5 | D11: 0.50694444
A12: 0.53819444 | B12: 0.55555556 | C12: 0.5625 | D12: /
A13: / | B13: / | C13: 0.6875 | D13: 0.69444444
A14: 0.70486111 | B14: 0.72222222 | C14: 0.75 | D14: 0.75694444
A15: 0.76736111 | B15: 0.78472222 | C15: 0.79166667 | D15: /
A17: Exceções
A19: Segunda-feira à Sexta-feira
A20: 1. No horário das 12h30min retorna para o início do Bairro São Cristóvão e aguarda para sair às 12h55min.
A21: 2. Na viagem das 16h55min sentido Bairro São Cristovão - Ponto da Rodoviaria, o intinerario executado será (Bairro São Cristóvão), Marginal Av. Tupi, Rua Alexandre Gusmão, Rua da Inconfidência, Rua Luiz Xavier, Rua Manoel Bandeira, Rua Vinte e Um de Abril, Rua Érico Verissimo, Rua Papa João XXIII, Av. Tupi, Av. Brasil, Rua Xingu, Rua Tamoio, PI 2, Rua Ararigboia, Rua Tocantins, P I 4, Rua Jaciretã, Av. Tupi, Trevo do Patinho, BR 158, Parque Industrial Theophilo Petrikoski, com chegada as 17h50min.
A22: 2. Na viagem das 17h20min sentido Ponto da Rodoviaria, o intinerario executado será, PI 2, Rua Iguaçu, Rua Guarani, Rua Farrapos, Av. Brasil , ponto rodoviária, Avenida Brasil, Trevo da Taísa, Marginal Av. Frei policarpo, Av. Frei Policarpo, Parque Industrial Theophilo Petrikoski (com chegada as 17h50min) , Av. Frei Policarpo, Trevo Patinho, Trevo Taísa, Marginal da Av. Frei Policarpo, Rua Paraná, Rua Farrapos, Avenida Brasil, ponto rodoviária
A24: SÁBADOS
A25: 1. Para na viagem das 13h30min.

Sheet 111
A1: Linha 111 - Fraron - UTFPR - Centro
A2: UTFPR, Av. Elisa Rosa Cola Padoan, Rua Irineu Parzianello, Rua Lídio Oltramari, Rua Angela Parzianello, Rua Vitélio Parzianello, Rua Benjamim Borges dos Santos, Rua Lídio Oltramari, Rua Clevelândia, Rua José Tato, Rua Martins Afonso de Souza, Rua Cristóvão Colombo, Rua José Dalmolin, Marginal da BR 158, Semafaro, Rua Paraná, Rua Farrapos, Rua Farrapos, Avenida Brasil (Ponto Rodoviária), Marginal BR 158, Rua Caramuru, Rua Tamoio, P I 3, Rua Ararigbóia, Rua Tocantins, Rua Jaciretã, Av. Tupi, PR 493, UTFPR.
A3: SEGUNDA-FEIRA À SEXTA-FEIRA
A4: UTFPR / Bairro Fraron | C4: P I 2 - Ponto Casa do Artesão
A5: 0.26736111 | C5: 0.29166667
A6: 0.30902778 | C6: 0.32638889
A7: 0.33680556 | C7: 0.35416667
A8: / | C8: 0.50347222
A9: 0.54166667 | C9: 0.55902778
A10: 0.56944444 | C10: 0.58680556
A11: / | C11: 0.6875
A12: 0.69791667 | C12: 0.71527778
A13: 0.72569444 | C13: 0.75694444
A14: 0.76736111 | C14: 0.78472222
A15: 0.79513889 | C15: 0.8125
A17: Exceções
A19: Segunda-feira à Sexta-feira
A20: 1. No horário das 12h20min retorna para UTFPR e aguarda para sair às 13h00min.
A21: 2. Nos horários das 06h25min, 13h00min e 17h25min no sentido UTFPR - PI3, é realizado o seguinte itinerário: UTFPR, Av. Elisa Rosa Cola Padoan, Rua Irineu Parzianello, Rua Lídio Oltramari, Rua Augusto Redivo, Rua Nelza Mazzuco Braun, Rua Hugo Luiz Scatezini, Rua Lidio Oltramari, Rua Angela Parzianello, Rua Vitélio Parzianello, Rua Benjamim Borges dos Santos, Rua Lídio Oltramari, Rua José Fraron, Rua Belmiro Michelin, Rua Elvira Gruber Weber, Rua José Mezzomo, Rua Orestes Armando Bertinato, Rua Belmiro Michelin, Rua José Faron, Lídio Oltramari, Rua Clevelândia, rota normal.
A23: SÁBADOS
A24: 1. É executado até às 08h30min.

Sheet 112
A1: Linha 112 - Planalto - Centro (via Rua Xingú)
A2: (Bairro Planalro), Rua Maracanã, Rua das Araras, Rua das Garças, Rua dos Cardeais, Rua Rua das Siriemas, Trevo Planalto, Marginal BR-158, Trevo Itacolomi, Rua Itacolomi, Rua Ubiratã, Rua Xingu, Rua Tamoio, P I 2, Rua Ararigbóia, Rua Tocantins, Rua Jaciretã, Av. Tupi, Rua Tapir, Rua Caramuru, P I 2, Rua Tamoio, Rua Itacolomi, Trevo Itacolomi, Marginal BR-158, Rua Maracanã.
A3: SEGUNDA-FEIRA À SEXTA-FEIRA
A4: Bairro Planalto (Rua Maracanã) | B4: P I 2 - Ponto Casa do Artesão (Rua Tamoio) | C4: Ponto Rua Tapir | D4: P I 2 - Ponto Casa do Artesão (Rua Tamoio)
A5: 0.25347222 | B5: 0.26736111 | C5: 0.27083333 | D5: 0.27430556
A6: 0.28125 | B6: 0.29513889 | C6: 0.29861111 | D6: 0.30208333
A7: 0.30902778 | B7: 0.32638889 | C7: 0.32986111 | D7: 0.33333333
A8: 0.34027778 | B8: 0.35416667 | C8: 0.35763889 | D8: 0.36111111
A9: 0.36805556 | B9: 0.38194444 | C9: 0.38541667 | D9: /
A10: / | B10: / | C10: 0.46875 | D10: 0.47222222
A11: 0.47916667 | B11: 0.49305556 | C11: 0.49652778 | D11: 0.50347222
A12: 0.51041667 | B12: 0.52083333 | C12: 0.52430556 | D12: 0.52777778
A13: 0.53819444 | B13: 0.55208333 | C13: 0.55555556 | D13: 0.55902778
A14: 0.56597222 | B14: 0.57986111 | C14: 0.58333333 | D14: /
A15: / | B15: / | C15: 0.66319444 | D15: 0.66666667
A16: 0.67361111 | B16: 0.6875 | C16: 0.69097222 | D16: 0.69444444
A17: 0.70138889 | B17: 0.71527778 | C17: 0.71875 | D17: 0.72222222
A18: 0.72916667 | B18: 0.74305556 | C18: 0.74652778 | D18: 0.75347222
A19: / | B19: / | C19: 0.75347222 | D19: 0.75694444 | E19: ATRASADO 10 MIN NO HORÁRIO 14-04-25
A20: 0.76388889 | B20: 0.77777778 | C20: 0.78125 | D20: /
A21: 0.76041667 | B21: 0.77430556 | C21: 0.77777778 | D21: 0.78125
A22: 0.78819444 | B22: 0.80208333 | C22: 0.80555556 | D22: 0.80902778
A23: 0.81597222 | B23: 0.82986111 | C23: 0.83333333 | D23: 0.83680556
A24: 0.84375 | B24: 0.85763889 | C24: 0.86111111 | D24: 0.86458333
A25: 0.87152778 | B25: 0.88541667 | C25: 0.88888889 | D25: 0.89236111
A26: 0.89930556 | B26: 0.91319444 | C26: 0.91666667 | D26: 0.92013889
A27: 0.92708333 | B27: 0.94097222 | C27: 0.94444444 | D27: 0.94791667
A28: 0.95486111 | B28: 0.97569444 | C28: 0.97916667 | D28: 0.98263889
A29: 0.98958333 | B29: 0.0069444444
A31: Exceções
A33: Segunda Feira a Sexta -Feira
A34: 1. Na viagem das 07h25min no sentido Bairro Planalto (Rua Maracanã) - P I 2, é realizado com o seguinte itinerário: Rua Maracanã, Rua das Araras, Rua das Garças, Rua dos Cardeais, Rua das Siriemas, Marginal da BR-158, Trevo da Guepardo, BR-158.
A35: 2. Na viagem das 17h30min no sentido Bairro Planalto (Rua Maracanã) - P I 2, é realizado com o seguinte itinerário: Rua Maracanã, Rua das Araras, Rua das Garças, Rua dos Cardeais, Rua das Siriemas, Marginal da BR-158, Rua Pioneiro Avelino Ardoino Chiochetta, Travessa Ademar Cantu, Rua Maria Daminellu Marini, Marginal da BR-158, Trevo da Guepardo, BR-158.
A36: 3. Na Viagem das 21h15min no sentindo PI2 - Rua Tapir, é realizado com o seguinte itinerário: P I 2, Rua Ararigbóia, Rua Tocantins, Rua Jaciretã, Av. Tupi, Rotatória do Anjo, Av. Tupi, Rua Tapir, Rua Caramuru, Rua Tamoio, PI2.
A37: 4. Nas Viagens das 22h40min e 23h30min no sentindo Rua Tapir - Bairro Planalto, é realizado com o seguinte itinerário: Rua Tapir, Rua Caramuru, PI 2, Rua Tamoio, Rua Itacolomi, Trevo Itacolomi, Marginal BR-158, Rua Édimo Belmiro Pastro.
A38: 5. Nas Viagens das 23h00min e 23h50min no sentindo Bairro Planalto - Rua Tapir , é realizado com o seguinte itinerário: Rua Édimo Belmiro Pastro (Bairro Bela Vista e Planalto), Rua das Andorinhas, (Bairro Paulo Afonso)Rua Aurea Zandona, Rua Augusto Saggin, Rua Abilio Parzianello, Rua Das Andorinhas, Rua das Garças, Rua dos Cardeais, (bairro Alto da Glória) Rua Mohamad Homar Awada, (Bairro São João, Bairro Vila São Pedro), Rua Clarice Recalcati, Rua Sadi Bertol, Rua Clarice Recalcati, Rua Mohamad Homar Awada, Rua dos Cardeais, Rua das Seriemas, Trevo Planalto, Marginal BR-158, Trevo Itacolomi, Rua Itacolomi, Rua Ubiratã, Rua Xingu, Rua Tamoio, P I 2, Rua Ararigbóia, Rua Tocantins, Rua Jaciretã, Av. Tupi, Rua Tapir
A40: SÁBADOS
A41: 1. É executada até a viagem das 13h25min. | E41: TERMINA A VIAGEM NO PI2
A42: 2. A partir das 16h00min é atendido pela Linha 113 - São João - Bela Vista - Paulo Afonso.

Sheet 113
A1: Linha 113 - SÃO JOÃO - BELA VISTA - PAULO AFONSO
A2: (Bairro São João), Rua Eugênio Pezarico, Rua Sadi Bertuol, Rua Clarice Recalcati, Rua Mohamad Homar Awada, Rua dos Cardeais (Bairro Planalto), Rua São Francisco de Assis, Rua Beija Flor, Rua Édimo Pastro, Rua das Andorinhas, Rua Aurea Zandoná, Rua Augusto Saggin, Rua Abílio Parzianello, Rua das Andorinhas, Rua Édimo Belmiro Pastro, Marginal BR 158, Br 158, Trevo Itacolomi, Rua Itacolomi, Rua Ubiratã, Rua Xingu, Rua Tamoio, P I 2, Rua Itabira, Rua Caramuru, (Ponto do Correio), Rua Tamoio, P I 2 (Casa do Artesão), Rua Itacolomi, Trevo Itacolomi, Marginal BR-158, Rua Arquimedes Gobato, Rua Pedro Luiz Tavares, Rua Édimo Belmiro Pastro, Rua das Andorinhas, Rua Aurea Zandoná, Rua Augusto Saggin, Rua Abílio Parzianello, Rua das Andorinhas, Rua Édimo Belmiro Pastro, Rua Beija Flor, Rua São Francisco de Assis, Rua dos Cardeais, Rua Mohamad Homar Awada, Rua Eugênio Pezarico.
A3: SEGUNDA-FEIRA À SEXTA
A4: Bairro São João (Rua Clarice Recalcati) | B4: Bairro Planalto (Rua das Siriemas) | C4: Bairro Bela Vista (Rua Édimo Belmiro Pastro) | D4: Ponto Correio (Rua Caramuru) | E4: P I 2 Ponto Casa do Artesão (Rua Tamoio)
A5: 0.23611111 | B5: 0.24305556 | C5: 0.24305556 | D5: 0.25555556 | E5: 0.25694444
A6: 0.27083333 | B6: / | C6: 0.28125 | D6: 0.29027778 | E6: 0.29166667
A7: 0.29166667 | B7: / | C7: 0.30208333 | D7: 0.31111111 | E7: 0.3125
A8: 0.3125 | B8: / | C8: 0.32291667 | D8: 0.33194444 | E8: 0.33333333
A9: 0.33333333 | B9: / | C9: 0.34375 | D9: 0.35277778 | E9: 0.35416667
A10: 0.35416667 | B10: / | C10: 0.36458333 | D10: 0.37361111 | E10: 0.375
A11: 0.39583333 | B11: / | C11: 0.40625 | D11: 0.41527778 | E11: 0.41666667
A12: 0.4375 | B12: / | C12: 0.44791667 | D12: 0.45694444 | E12: 0.45833333
A13: / | B13: / | C13: / | D13: / | E13: 0.47916667
A14: 0.47916667 | B14: / | C14: 0.48958333 | D14: 0.49861111 | E14: 0.50347222
A15: 0.5 | B15: / | C15: 0.51041667 | D15: 0.51944444 | E15: 0.52083333
A16: 0.53125 | B16: 0.53819444 | C16: / | D16: 0.55 | E16: 0.55208333
A17: 0.54166667 | B17: / | C17: 0.55208333 | D17: 0.56111111 | E17: 0.5625
A18: 0.57291667 | B18: / | C18: 0.58333333 | D18: 0.59166667 | E18: 0.59375
A19: 0.58333333 | B19: / | C19: 0.59375 | D19: 0.60277778 | E19: 0.60416667
A20: 0.625 | B20: / | C20: 0.63541667 | D20: 0.64444444 | E20: 0.64583333
A21: 0.66666667 | B21: / | C21: 0.67708333 | D21: 0.68611111 | E21: 0.6875
A22: 0.70833333 | B22: / | C22: 0.71875 | D22: 0.72777778 | E22: 0.72916667
A23: / | B23: / | C23: / | D23: / | E23: 0.75347222
A24: 0.75 | B24: / | C24: 0.76041667 | D24: 0.76944444 | E24: 0.77083333
A25: 0.77083333 | B25: / | C25: 0.78125 | D25: 0.79027778 | E25: 0.79166667
A26: 0.79166667 | B26: / | C26: 0.80208333 | D26: 0.81111111 | E26: 0.8125
A27: 0.8125 | B27: / | C27: 0.82291667 | D27: 0.83194444 | E27: 0.83333333
A28: 0.85416667 | B28: / | C28: / | D28: / | E28: /
A29: Linha 113 - PLANALTO - SÃO JOÃO - BELA VISTA - PAULO AFONSO
A30: (Bairro Bela Vista e Bairro Planalto), Rua Édimo Belmiro Pastro, Rua das Andorinhas, (Bairro Paulo Afonso), Rua Aurea Zandoná, Rua Augusto Saggin, Rua Abílio Parzianello, Rua das Andorinhas, Rua das Garças, Rua dos Cardeais, (Bairro Alto da Glória), Rua Mohamad Homar Awada, (Bairro São João, Bairro Vila São Pedro), Rua Eugênio Pezarico, Rua Sadi Bertol, Rua Clarice Recalcati, Rua Mohamad Homar Awada, Rua dos Cardeais, Rua das Seriemas, Trevo Planalto, BR-158, Trevo Itacolomi, Rua Itacolomi, Rua Itabira, Rua Caetano Munhos da Rocha, Rua Vereador Cacique Creta, Rua Vitor Silvio Biazus, Rua Paraná, Rua Farrapos, Rua Caramuru, P I 2, Rua Itacolomi, Trevo Itacolomi, BR-158, (Trevo Planalto), Marginal BR 158, Rua Édimo Belmiro Pastro, (Bairro Bela Vista).
A31: SÁBADOS
A32: Bairro São João | B32: Ponto Rodoviária | C32: P I 2 Ponto Casa do Artesão (Rua Tamoio) | D32: Bairro Bela Vista (Rua Édimo Belmiro Pastro)
A33: / | B33: 0.57638889 | C33: 0.58333333 | D33: 0.59027778
A34: 0.60416667 | B34: 0.61805556 | C34: 0.625 | D34: 0.63194444
A35: 0.64583333 | B35: 0.65972222 | C35: 0.66666667 | D35: 0.67361111
A36: 0.6875 | B36: 0.70138889 | C36: 0.70833333 | D36: 0.71527778
A37: 0.72916667 | B37: 0.74305556 | C37: 0.75 | D37: 0.75694444
A38: 0.77083333 | B38: 0.78472222 | C38: 0.79166667 | D38: 0.79861111
A39: 0.8125 | B39: 0.82638889 | C39: 0.83333333 | D39: 0.84027778
A40: 0.85416667 | B40: 0.86805556 | C40: 0.875 | D40: 0.88194444
...

Sheet 114
A1: Linha 114 - SÃO ROQUE - VILA VERDE - VILA ESPERANÇA
A2: (Bairro São Roque), Rua Wilibat, Rua Riberão Preto, Rua Taubaté, Rua Marilia, Rua Terezinha Duarte, Rua Ivaí, Rua Zacarias de Gois e Vasconcelos, Rua Xavier da Silva, Rua Lupicínio Rodrigues, Rua Amambaí, Rua Iguatemi, Rua Genuíno Piacentini, Rua Xingú, Rua Tamoio, P I 2, Rua Iguaçu, Rua Guarani, Rua Farrapos, Av. Brasil, Trevo BR 158, Rua José Leonardi, Rua Vinícius de Moraes, Rua Marco Penso, Rua Moacir José Martins, Marginal BR 158, SEMÁFORO, Rua Paraná, Rua Farrapos (Ponto Rodoviária), Rua Caramuru, P I 1, Rua Tamoio, Rua Xavantes, Rua Genuíno Piacentini, Rua Iguatemi, Rua Amambaí, Rua Lupicínio Rodrigues, Rua Wilibat.
A3: SEGUNDA-FEIRA À SEXTA - FEIRA
A4: São Roque ( Rua Wilibat) | B4: São Cristóvão (Rua Alexandre Gusmão) | C4: São Roque (Rua Wilibat) | D4: P I 2 Ponto Casa do Artesão (Rua Tamoio) | E4: Bairro Vila Esperança | F4: P I 1 - Ponto Casa do Artesão (Rua Caramuru)
A5: / | D5: / | E5: / | F5: 0.25694444
A6: / | D6: 0.26041667 | E6: 0.27083333 | F6: 0.28472222
A7: 0.26388889 | D7: 0.28125 | E7: / | F7: /
A8: 0.26736111 | D8: 0.28472222 | E8: 0.29513889 | F8: 0.3125
A9: 0.29513889 | D9: 0.3125 | E9: 0.32291667 | F9: 0.34027778
A10: 0.32291667 | D10: 0.34027778 | E10: 0.35069444 | F10: 0.36805556
A11: 0.35069444 | D11: 0.36805556 | E11: 0.37847222 | F11: 0.39583333
A12: 0.37847222 | D12: 0.39583333 | E12: / | F12: /
A13: / | D13: / | E13: / | F13: 0.45138889
A14: / | D14: 0.45138889 | E14: 0.46180556 | F14: 0.47916667
A15: 0.46180556 | D15: 0.47916667 | E15: 0.48958333 | F15: 0.50347222
A16: 0.48958333 | D16: 0.50347222 | E16: 0.51736111 | F16: 0.53472222
A17: 0.51736111 | D17: 0.53472222 | E17: 0.54513889 | F17: 0.5625
A18: 0.54861111 | D18: 0.5625 | E18: 0.57638889 | F18: 0.59027778
A19: 0.57638889 | B19: 0.57847222 | C19: 0.58333333 | D19: 0.59722222 | E19: 0.60763889 | F19: 0.61805556
A20: 0.60069444 | D20: 0.61805556 | E20: 0.62847222 | F20: 0.64583333
A21: 0.63194444 | B21: 0.63402778 | C21: 0.63888889 | D21: 0.65277778 | E21: 0.66319444 | F21: 0.67361111
A22: 0.65625 | D22: 0.67361111 | E22: 0.68402778 | F22: 0.70138889
A23: 0.6875 | B23: 0.68958333 | C23: 0.69444444 | D23: 0.70833333 | E23: 0.71875 | F23: 0.72916667
A24: 0.71180556 | D24: 0.72916667 | E24: 0.73958333 | F24: 0.75694444
A25: 0.73958333 | D25: 0.75694444 | E25: 0.76736111 | F25: 0.78472222
A26: 0.76736111 | D26: 0.78472222 | E26: 0.79513889 | F26: 0.8125
A27: 0.79513889 | D27: 0.8125 | E27: 0.82291667 | F27: /
A28: / | B28: 0.82291667 | C28: 0.83333333 | D28: 0.84375 | E28: 0.85416667 | F28: 0.86458333
A29: / | B29: 0.875 | C29: 0.88194444 | D29: 0.89583333 | E29: / | F29: /
A31: Exceções
A33: Segunda-feira à Sexta-feira
A34: 1. Nas viagens 07h05min, 07h45min, 12h25min, 13h05min, 18h25min e 19h05min no sentido Bairro Vila Esperança - P I 1, inclui-se no intinerário a Estrada Irineu Bertani, Rua Pedro Kriger, Rua Saul Viganó, Rua Jacob Gugelmin, Estrada Irineu Bertani, Rua Tobias José Nesi (Bairro Pagnoncelli), Rua Rafael Lopes dos Santos (até Rua Claudino Gresele),Rua Tobias José Nesi Estrada Irineu Bertani, Rua José Leonardi.
A35: 2. Nas viagens das 19h30min e 20h50min no sentido P I 1 - Bairro São Roque, o intineráio será executado da seguinda forma: P I 1, Rua Tamoio, Av. Tupi, Marginal da Av. Tupi, Rua Alexandre Gusmão, Rua da Inconfidência, Rua Luiz Xavier, Rua Manoel Bandeira, Rua Vinte e Um de Abril, Rua Érico Veríssimo, Rua Papa João XXIII, Rua Manoel Bandeira, Rua Antônio Garcês, Rua R. da República, Rua Papa João XXIII, Av. Tupi, Rua Ribeirão Preto, (Bairro São Roque).
A36: 3. Nas viagens das 13h30min, 14h50min e 16h10min no sentido PI1 - Bairro São Roque, o itinerário será executado na seguinte forma: P I 1, Rua Tamoio, Rua Xavantes, Rua Genuíno Piacentini, Rua Iguatemi, Rua Amambaí, Rua Lupicínio Rodrigues, Rua Wilibat, Rua Ribeirão Preto, SEMÁFORO, Av. Tupi, Marginal Av. Tupi, Rua Alexandre Gusmão, Rua da Inconfidência, Rua Luiz Xavier, Rua Manoel Bandeira, Rua Vinte e Um de Abril, Rua Érico Veríssimo, Rua Papa João XXIII, Rua Manoel Bandeira, Rua Antônio Garcês, Rua R. da República, Rua Papa João XXIII, Av. Tupi, Rua Ribeirão Preto, (Bairro São Roque).
A37: 4.O Carro 03 é executado de Segunda - Feira à Sexta - Feira.
A39: SÁBADOS
A40: 1. Nas viagens das 07h05min, 07h45min,12h25min e 13h05min no sentido Bairro Vila Esperança - P I 1, inclui-se no intinerário a Estrada Irineu Bertani, Rua Pedro Kriger, Rua Saul Viganó, Rua Jacob Gugelmin, Estrada Irineu Bertani, Rua TobiasJosé Nesi (Bairro Pagnoncelli), Rua Rafael Lopes dos Santos (até Rua Claudino Gresele), Rua Tobias José Nesi, Estrada Irineu Bertani, Rua José Leonardi.
A41: 2. Aos sábados executa-se o itinerário até a viagem das 14h10min e 14h20min.
A43: CARRO 01
A44: CARRO 02
...

Sheet 115
A1: Linha 115 - Planalto - Centro (via Rodoviária)
A2: (Bairro Planalto), Rua Maracanã, Rua das Araras, Rua das Garças, Rua dos Cardeais, Rua das Siriemas, Trevo Planalto, Marginal BR-158, Trevo Itacolomi, Rua Itacolomi, Rua Afonso Pena (Bairro Menino Deus, BHF e Jardim Primavera), Rua Caetano Munhos da Rocha, Rua Vereador Cacique Creta, Rua Victor Sílvio Biazus, Rua Paraná, Rua Farrapos, Av. Brasil, (Ponto Rodoviária), Marginal Br 158, Rua Nereu Ramos, Rua Caramuru, P I 2, Rua Tamoio, Rua Itacolomi, Trevo Itacolomi, Marginal BR 158, (Bairro Planalto).
A3: SEGUNDA-FEIRA À SEXTA-FEIRA
A4: Bairro Planalto (Rua Maracanã) | B4: Ponto Rodoviária | C4: P I 2 Ponto Casa do Artesão (Rua Tamoio)
A5: 0.27083333 | B5: 0.28472222 | C5: 0.29166667
A6: 0.29861111 | B6: 0.3125 | C6: 0.31944444
A7: 0.32638889 | B7: 0.34027778 | C7: 0.34722222
A8: 0.35416667 | B8: 0.36805556 | C8: 0.375
A9: 0.38194444 | B9: 0.39583333 | C9: 0.40277778
A10: 0.40972222 | B10: 0.42361111 | C10: 0.43055556
A11: 0.4375 | B11: 0.45138889 | C11: 0.45833333
A12: 0.46527778 | B12: 0.47916667 | C12: 0.48611111
A13: 0.49305556 | B13: 0.50694444 | C13: 0.51388889
A14: 0.52083333 | B14: 0.53472222 | C14: 0.54166667
A15: 0.54861111 | B15: 0.5625 | C15: 0.56944444
A16: 0.57638889 | B16: 0.59027778 | C16: 0.59722222
... A24: 0.79861111 | B24: 0.8125 | C24: 0.81944444
A26: Exceções
A28: Segunda-feira à Sexta-feira
A29: 1. Na Viagem das 07h10min no sentido Bairro Planalto (Rua Maracanã) - P I 2, é realizado o itinerário da seguinte forma: Rua Maracanã, Rua das Araras, Rua das Garças, Rua dos Cardeais, Rua das Siriemas, Marginal da BR-158, Trevo da Guepardo, BR-158.
A31: SÁBADOS
A32: 1. É executada até a viagem das 13h40min.
A33: 2. A partir das 15h50min é realizado pela Linha 113 São João - Bella Vista - Paulo Afonso.

Sheet 116
A1: Linha 116 - Nova Espero
A2: P I 3, Rua Tamoio, Rua Ararigbóia, Rua Tocantins, PI 4, Rua Jaciretã, Av. Tupi, Trevo Patinho, BR-158, (Nova Espero), Rua Câmara Junior, Rua Santo Agostinho (Ponto Aramart), Rua José Tirloni, Rua Armando Setti, Rua 14 de Dezembro, Rua David Tirloni, Rua Câmara Junior, BR-158, Trevo Patinho, Trevo Taísa, Rua Nereu Ramos, Rua Caramuru, Rua Itacolomi, Rua Tamoio, P I 3.
A3: SEGUNDA-FEIRA À SEXTA-FEIRA
A4: P I 2 Ponto Casa do Artesão (Rua Tamoio) | B4: P I 4 Ponto Pavilhão São Pedro | C4: Ponto Atlas | D4: Bairro Nova Espero | E4: Ponto Atlas
A5: 0.25694444 | B5: 0.25902778 | C5: 0.27430556 | D5: 0.27777778 | E5: /
A6: 0.30208333 | B6: 0.30416667 | C6: 0.31597222 | D6: 0.31944444 | E6: /
A7: 0.34027778 | B7: / | C7: / | D7: / | E7: /
A8: 0.47916667 | B8: 0.48125 | C8: 0.49652778 | D8: 0.5 | E8: /
A9: 0.52083333 | B9: 0.52291667 | C9: 0.53819444 | D9: 0.54166667 | E9: /
A10: 0.56597222 | B10: / | C10: / | D10: / | E10: /
A11: 0.70138889 | B11: 0.70347222 | C11: / | D11: 0.71875 | E11: 0.73263889
A12: 0.75347222 | B12: 0.75555556 | C12: / | D12: 0.77083333 | E12: 0.77430556
A13: 0.79166667 | B13: / | C13: / | D13: / | E13: /
A15: SÁBADOS
A16: P I 2 Ponto Casa do Artesão (Rua Tamoio) | B16: P I 4 Ponto Pavilhão São Pedro | C16: Ponto Atlas | D16: Bairro Nova Espero | E16: Ponto Atlas
A17: 0.25694444 | B17: 0.25902778 | C17: 0.27430556 | D17: 0.27777778 | E17: /
A18: 0.29861111 | B18: / | C18: / | D18: /
A19: 0.47916667 | B19: 0.48125 | C19: 0.49652778 | D19: 0.5
A20: 0.52083333 | B20: 0.52430556 | C20: / | D20: 0.54166667
A21: 0.5625
A23: Exceções
A25: Segunda-feira à Sexta-feira
A26: 1. Na viagem das 17h15min sentido Bairro Nova Espero - P I 3 ao chegar no Ponto Atlas aguarda-se para partir às 17h35min.

Sheet 117
A1: Linha 117 - Planalto - UTFPR - UNIDEP
A2: (Shopping Pato Branco) Avenida da Inovação, Avenida Tupi, Trevo do Patinho, PR-493, UTFPR, Rua Eliza Cola Padoan, Rua Irineu Parzianello, Rua Lidio Oltramari, Rua Benjamim Borges dos Santos, UNIDEP, PR-493, Trevo Patinho, Marginal BR-158, Trevo da Taísa, Rua José Leonardi, Rua Vinícius de Moraes, Rua Marco Penso, Rua Moacir José Martins, Marginal BR 158, SEMÁFORO, Rua Paraná, Rua Farrapos, Avenida Brasil (Ponto da Rodoviaria), Rua Maria Bueno, Rua Dez de Maio, Rua Victor Sílvio Biazus, Rua Vereador Cacique Creta, Rua Caetano Munhos da Rocha, Rua Itabira, Rua Afonso Pena, Rua Itacolomi, Trevo Itacolomi, Marginal BR 158, Rua Édimo Belmiro Pastro, (Bairro Bela Vista), Rua das Andorinhas, Ruas das Garças, Rua dos Cardeais, Rua das Siriemas, (Bairro Planalto).
A3: SEGUNDA-FEIRA À SEXTA-FEIRA
A4: Ponto Rodoviária | B4: Bairro Planalto | C4: Shopping Pato Branco | D4: UTFPR - UNIDEP
A5: / | B5: / | C5: 0.94791667 | D5: 0.96180556
A6: 0.97222222 | B6: 0.98611111 | C6: / | D6: /

Sheet 119
A1: Linha 119 - SHOPPING PATO BRANCO / SÃO FRANCISCO
A2: (Bairro São Francisco), Rua Artibano Sutile, Rua Vitorino Tiocheta, Rua Dionisio D. Sauthier, Rua Celito Giacomel, Rua Pioneiro Victório Leonardi, Rua Melci Dalmolin, Rua Artibano Sutille, Trevo CAPEG, Marginal BR-158, Parque Teophilo Petrikoski, BR 158, Trevo do Patinho, Avenida Tupi, Rua Tapir, Rua Caramuru, Rua Tamoio, P I 2, Rua Tamoio, Rua Ararigbóia, Rua Tocantins, Rua Jaciretâ, Avenida Tupi, Avenida da Inovação (Shopping Pato Branco), Rua Hilda Maria Colla, Rua Abel Bortot, Estrada Municipal, Rua Abrosio Bez, Rua Carmela Bortot, Rua Tocantins, Rua Artibano Sutile.
A3: SEGUNDA-FEIRA À SEXTA -FEIRA
A4: P I 2 - Ponto Casa do Artesão (Rua Tamoio) | B4: Avenida da Inovação (Shopping Pato Branco) | C4: Bairro São Luiz (Rua Amborsio Bez) | D4: Bairro São Francisco (Primeiro Ponto da Rua Artibano Sutile sentido Bairro São Francisco) | E4: Avenida da Inovação (Shopping Pato Branco) | F4: UTFPR / UNIDEP
A5: 0.25 | B5: 0.25694444 | C5: 0.26041667 | D5: 0.26388889 | E5: / | F5: /
A6: 0.28125 | B6: 0.29166667 | C6: 0.29513889 | D6: 0.29861111 | E6: / | F6: /
A7: 0.31597222 | B7: 0.32638889 | C7: 0.32986111 | D7: 0.33333333 | E7: / | F7: /
A8: 0.35069444 | B8: 0.36111111 | C8: 0.36458333 | D8: 0.36805556 | E8: / | F8: /
A9: 0.38888889 | B9: 0.39930556 | C9: / | D9: 0.40625 | E9: 0.41319444 | F9: /
A10: 0.42708333 | B10: 0.4375 | C10: 0.44097222 | D10: / | E10: / | F10: /
A11: 0.44791667 | B11: 0.45833333 | C11: 0.46180556 | D11: / | E11: / | F11: /
A12: 0.46875 | B12: 0.47916667 | C12: 0.48263889 | D12: 0.48611111 | E12: / | F12: /
A13: 0.5 | B13: 0.51041667 | C13: 0.51388889 | D13: 0.51736111 | E13: / | F13: /
A14: 0.53125 | B14: 0.54166667 | C14: 0.54513889 | D14: 0.54861111 | E14: / | F14: /
A15: 0.56597222 | B15: 0.57638889 | C15: 0.57986111 | D15: 0.58333333 | E15: / | F15: /
A16: 0.59722222 | B16: 0.60763889 | C16: 0.61111111 | D16: 0.61458333 | E16: / | F16: /
A17: 0.62847222 | B17: 0.63888889 | C17: 0.64236111 | D17: 0.64583333 | E17: / | F17: /
A18: 0.65972222 | B18: 0.67013889 | C18: 0.67361111 | D18: 0.67708333 | E18: / | F18: /
A19: 0.69097222 | B19: 0.70138889 | C19: / | D19: 0.70833333 | E19: 0.71527778 | F19: /
A20: 0.72222222 | B20: 0.73263889 | C20: 0.73611111 | D20: 0.73958333 | E20: / | F20: /
A21: 0.75694444 | B21: 0.76736111 | C21: 0.77083333 | D21: 0.77430556 | E21: / | F21: /
A22: 0.77083333 | B22: 0.78125 | C22: / | D22: 0.78472222 | E22: / | F22: /
A23: 0.79166667
A24: 0.79861111 | B24: 0.8125 | C24: / | D24: / | E24: / | F24: 0.81944444
A25: 0.83333333 | B25: 0.84722222 | C25: / | D25: / | E25: / | F25: 0.85416667
A26: 0.86805556 | B26: 0.88194444 | C26: / | D26: / | E26: / | F26: 0.88888889
A27: 0.90277778 | B27: 0.92361111 | C27: / | D27: 0.92708333 | E27: / | F27: /
A28: 0.94097222 | B28: 0.96180556
A29: 0.97569444
A31: Shopping Pato Branco - UTFPR - Centro
A32: SÁBADOS
A33: (Shopping Pato Branco) Avenida da Inovação, Avenida Tupi, Trevo do Patinho, Avenida Tupi, Rua Tapir, Rua Caramuru, Rua Tamoio, P I 1, Rua Tamoio, Av. Tupi, Marginal Av. Tupi, Rua das Flores, Rua Princesa Isabel, Rua Jaury Heitor de Souza (Bairro Gralha Azul), Rua Ricieri Pastori, Rua Marcelino Parzianello, Rua das Flores, Marginal Av. Tupi, Av. Tupi, Rua Bento Gonçalves, Rua General Osório, Rua Curitiba, Rua das Acácias, Rua Bento Gonçalves, Rua das Hortências, Rua Antônio Ascari, Rua Tocantins, Avenida da Inovação.
A34: Avenida da Inovação (Shopping Pato Branco) | B34: P I 1 Ponto Casa do Artesão (Rua Caramuru) | C34: Bairro Gralha Azul | D34: Bairro Veneza | E34: P I 4 Ponto Pavilhão São Pedro
A35: 0.92013889 | B35: 0.93055556 | C35: 0.94097222 | D35: 0.94791667 | E35: 0.95486111
A36: 0.96180556 | B36: 0.97222222 | C36: 0.98263889 | D36: 0.98958333 | E36: 0.99652778
A38: Shopping Pato Branco) Avenida da Inovação, Rua Tocantins, Rua Artibano Sutile, Rua Gelmino Martignone, Rua Melci Dal Molim, Rua Artibano Sutile, Trevo CAPEG, Marginal BR-158, Parque Teophilo Petrikoski, BR 158, Trevo do Patinho,Marginal da BR-158, Trevo da Taisa, Rua Moacir de Jesus Martins, Rua Março Penso, Rua Vinivius de Moraes, Rua José Leonardi, Rua Irineu Bertani, Rua Mohammed Omar Awada, Rua dos Cardeais, Rua das Seriemas, Trevo Planalto, BR-158, Marginal BR 158,Trevo Itacolomi, Rua Itacolomi, Rua Ubiratã, Rua Xingú, Rua Tamoio (PI2), Rua Tamoio, Rua Araribóia, Rua Tocantins, Avenida da Inovação.
A39: Avenida da Inovação (Shopping Pato Branco) | B39: Bairro São Francisco (Primeiro Ponto da Rua Artibano Sutile sentido Bairro São Francisco) | C39: Bairro Vila Esperança | D39: Bairro Planalto | E39: P I 2 - Ponto Casa do Artesão (Rua Tamoio)
A40: 0.92013889 | B40: 0.92708333 | C40: 0.9375 | D40: 0.94791667 | E40: 0.95486111
A41: 0.96180556 | B41: 0.96875 | C41: 0.97916667 | D41: 0.98958333 | E41: 0.99652778
A43: Shopping Pato Branco - UTFPR - Centro
...

Sheet 201
A1: Linha 201 - Gralha Azul - Vibra
A2: P I 3, Rua Tamoio, Trevo Taísa, Trevo Patinho, PR-493, Vibra, PR-493, Trevo Patinho, BR-158, Rua Artibano Sutile, Rua Vitório Tiocheta, Rua Dionísio Daniel Sautier, Rua Celito Giacomel, Rua Pioneiro Victório Leonardi, Rua Melci Dalmolin, Rua Artibano Sutile, Rua Tocantins, Rua Itacolomi, Rua Caramuru, P I 1, Rua Tamoio, Av. Tupi, Rua Dr. Beltrão, Rua Santa Fé, Rua Industrial, Rua Fernando Ferrari, Rua Anchieta, Rua Fernando Ferrari, Rua Angelo Dal Bosco, Rua das Violetas, Rua Curitiba, Rua General Osório, Rua Tiradentes, Rua Princesa Isabel, Rua Jaury Heitor de Souza, Rua Riciere Pastore, Rua Marcelino Parzianello, Rua Princesa Isabel, Av. Tupi, Av. Brasil, Rua Xingú, Rua Tamoio, P I 2.
A3: SEGUNDA-FEIRA À SEXTA-FEIRA
A4: Vibra | B4: P I 1 - Casa do Artesão (Rua Caramuru) | C4: Bairro Gralha Azul | D4: P I 2 - Casa do Artesão (Rua Tamoio)
A5: / | B5: / | C5: / | D5: 0.0034722222
A6: 0.0069444444 | B6: 0.017361111 | C6: 0.034722222 | D6: /
A7: 0.076388889 | B7: 0.090277778 | C7: 0.11111111 | D7: /
A8: 0.59722222 | B8: 0.61111111 | C8: 0.62152778 | D8: 0.63194444
A9: 0.66666667 | B9: 0.68055556 | C9: 0.70138889 | D9: 0.71527778
A11: P I 1, Rua Caramuru, Rua Tamoio, Av. Tupi, Marginal Av. Tupi, Rua das Flores, Rua Princesa Isabel, Rua Jaury Heitor de Souza, (Bairro Gralha Azul), Rua Riciere Pastore, Rua Marcelino Parzianello, Rua Princesa Isabel, Rua Tiradentes, General Osório, Rua Curitiba, Rua das Acácias, Rua Angelo Dal Bosco, Rua Fernando Ferrari, Rua Anchieta, Rua Fernando Ferrari, Rua Industrial, Rua Santa Fé, Rua Dr. Beltrão, Av. Tupi, Av. Brasil, Rua Xingú, Rua Tamoio, P I 3, Rua Tamoio, Rua Ararigbóia, Rua Tocantins, Rua Artibano Sutile, Rua Vitório Tiocheta, Rua Dionísio Daniel Sautier, Rua Celito Giacomel, Rua Pioneiro Victório Leonardi, Rua Melci Dalmolin, Rua Artibano Sutile, BR-158, PR 493, Vibra.
A12: SEGUNDA-FEIRA À SEXTA-FEIRA
A13: Bairro Gralha Azul | B13: P I 2 - Casa do Artesão (Rua Tamoio) | C13: Vibra | D13: P I 2 - Casa do Artesão (Rua Tamoio)
A14: 0.11458333 | B14: 0.12847222 | C14: 0.14583333 | D14: /
A15: 0.18055556 | B15: 0.19791667 | C15: 0.22222222 | D15: /
A16: / | B16: / | C16: / | D16: 0.51041667
A17: 0.52083333 | B17: 0.54166667 | C17: 0.5625 | D17: / | E17: Carro 01
A18: / | B18: / | C18: / | D18: 0.59375
A19: 0.60416667 | B19: 0.625 | C19: 0.64583333 | D19: / | E19: Carro 02

Sheet 202
A1: Linha 202 - Planalto - Vibra
A2: Ponto Rodoviária, Av. Brasil, Trevo Taísa, BR-158, Trevo Patinho, PR-493, Vibra, PR-493, UTFPR, Rua Irineu Parzianello, Rua Lídio Oltramari, Rua Clevelândia, Rua José Tato, Rua Martins Afonso de Souza, Marginal BR-158, Trevo Taísa, Rua Moacir de Jesus Martins, Rua Marco Penso, Rua Vinícius de Moaraes, Rua José Leonardi, Rua Irineu Bertani, Rua Mohammed Omar Awada, Rua dos Cardeais, Rua das Garças, Rua das Andorinhas, Rua Áurea Zandoná, Rua Augusto Saggin, Rua Abílio Parzianello, Rua Das Andorinhas, Rua Édimo Belmiro Pastro.
A3: SEGUNDA-FEIRA À SEXTA-FEIRA
A4: Vibra | B4: Bairro Bela Vista | C4: Ponto Rodoviaria
A5: / | B5: / | C5: 0.0034722222
A6: 0.0069444444 | B6: 0.038194444 | C6: /
A7: 0.076388889 | B7: 0.11111111 | C7: /
A8: 0.59722222 | B8: 0.61805556 | C8: /
A9: 0.66666667 | B9: 0.70138889 | C9: /
A11: Ponto Rodoviária, Av. Brasil, Trevo Taísa, BR-158, Trevo Itacolomi, Marginal BR-158, Rua Édimo Belmiro Pastro, Rua das Andorinhas, Rua Áurea Zandoná, Rua Augusto Saggin, Rua Abílio Parzianello, Rua das Andorinhas, Rua das Garças, Rua dos Cardeais, Rua Mohammad Omar Awada, Rua Irineu Bertani, Rua José Leonardi, Rua Vinícius de Moraes, Rua Marco Penso, Rua Moacir de Jesus Martins, Marginal BR-158, Rua Martins Afonso de Souza, Rua José Tato, Rua José Fraron, Rua Lídio Oltramari, Rua lrineu Parzianello, Trevo UTFPR, PR-493, Vibra.
A12: SEGUNDA-FEIRA À SEXTA-FEIRA
A13: Bairro Bela Vista | B13: Vibra | C13: Ponto Rodoviária
A14: 0.12152778 | B14: 0.14930556 | C14: /
A15: 0.20138889 | B15: 0.22916667 | C15: /
A16: / | B16: / | C16: 0.52777778
A17: 0.53472222 | B17: 0.56597222 | C17: /
A18: / | B18: / | C18: 0.60416667
A19: 0.61111111 | B19: 0.64583333 | C19: /

Sheet 205
A1: Linha 205 - São Cristóvão - Centro - Vibra
A2: Ponto Rodoviária, Av. Brasil, Trevo Taísa, BR-158, Trevo Patinho, PR-493, Vibra, PR-493, Av. Tupi, Rua Tapir, Rua Caramuru, P I 1, Rua Tamoio, Av. Tupi, (Bairro São Cristóvão), Rua Alexandre Gusmão, Rua da Inconfidência, Rua Luiz Xavier, Rua Manoel Bandeira, Rua Vinte Um de Abril, Rua Érico Veríssimo, Rua Papa João XXIII, Av. Tupi, Rua Ribeirão Preto, Rua Taubaté, (Bairro São Roque), Rua Marília, Rua Terezinha Duarte, (Bairro Santa Fé), Rua Ivaí, (Bairro Vila Verde e Pinheirinho), Rua Lupicínio Rodrigues, Rua Amambaí, Rua Pedro José da Silva, Rua Iguatemi, Rua Genuíno Piacentini, (Bairro Santa Terezinha), Rua Xingú, Rua Tamoio, P I 2.
A3: SEGUNDA-FEIRA À SEXTA-FEIRA
A4: Vibra | B4: Bairro São Cristóvão | C4: P I 2 - Casa do Artesão (Rua Caramuru) | D4: Ponto Rodoviária
A5: / | B5: / | C5: / | D5: 0.0034722222
A6: 0.0069444444 | B6: 0.03125 | C6: 0.048611111 | D6: /
A7: 0.076388889 | B7: 0.090277778 | C7: 0.10416667 | D7: /
A8: 0.59722222 | B8: 0.62152778 | C8: 0.63888889 | D8: /
A9: 0.66666667 | B9: 0.69097222 | C9: 0.70833333 | D9: /
A10: / | B10: / | C10: / | D10: /
A12: P I 1, Rua Caramuru, Rua Tamoio, Av. Tupi, Marginal Av. Tupi, (Bairro São Cristóvão), Rua Alexandre Gusmão, Rua da Inconfidência, Rua Luiz Xavier, Rua Manoel Bandeira, Rua Vinte Um de Abril, Rua Érico Veríssimo, Rua Papa João XXIII, Av. Tupi, Rua Ribeirão Preto, Rua Taubaté, (Bairro São Roque), Rua Marília, Rua Terezinha Duarte, (Bairro Santa Fé), Rua Ivaí, (Bairro Vila Verde e Pinheirinho), Rua Lupicínio Rodrigues, Rua Amambaí, Rua Pedro José da Silva, Rua Iguatemi, Rua Genuíno Piacentini, (Bairro Santa Terezinha), Rua Xingú, Rua Tamoio, P I 3, Rua Tamoio, Rua Ararigbóia, Rua Tocantins, Rua Jaciretã, Av. Tupi, PR-493, Vibra.
A13: SEGUNDA-FEIRA À SEXTA-FEIRA
A14: P I 1 - Casa do Artesão (Rua Caramuru) | B14: Bairro São Cristovão | C14: P I 3 - Antiga Rodoviária (Rua Tamoio) | D14: Vibra
A15: / | B15: 0.11805556 | C15: 0.13541667 | D15: 0.14930556
A16: / | B16: 0.19791667 | C16: 0.21527778 | D16: 0.22916667
A17: 0.52777778 | B17: 0.53472222 | C17: 0.55208333 | D17: 0.56597222
A18: 0.60763889 | B18: 0.61458333 | C18: 0.63194444 | D18: 0.64583333

Sheet 206
A1: Linha 206 - Centro Pq. Industrial 03 - Vibra
A2: P I 3, Rua Tamoio, Trevo Taísa, BR-158, Trevo Patinho, PR-493, Estrada Municipal, Vibra, PR-493, Trevo Patinho, Av. Tupi, Rua Tapir, Rua Caramuru, Rua Tamoio, P I 3, Rua Tamoio, Avenida Tupi, (Trevo da Patrola).
A3: SEGUNDA-FEIRA À SEXTA-FEIRA
A4: Vibra | B4: P I 2 - Casa do Artesão (Rua Tamoio) | C4: Trevo Patrola | D4: P I 2 - Casa do Artesão (Rua Tamoio)
A5: / | B5: / | C5: / | D5: 0.065972222
A6: 0.076388889 | B6: 0.090277778 | C6: 0.11111111 | D6: /
A7: / | B7: / | C7: / | D7: /
A9: Linha 206 - Centro Pq. Industrial 03 - Vibra
A10: P I 3, Rua Ararigbóia, Rua Tocantins, Rua Jaciretã, Av. Tupi, Trevo do Patinho, PR-493, Estrada Municipal, Vibra.
A11: SEGUNDA-FEIRA À SEXTA-FEIRA
A12: PI 3 Antiga Rodoviária (Rua Tamoio) | C12: Vibra
A13: 0.27083333 | C13: 0.28472222 | E13: a partir do dia 13/03 carro MINI
A15: Linha 206 - Centro Pq. Industrial 03 - Vibra
A16: Rua Curitiba, Rua das Acácias, Rua Angelo Dal Bosco, Rua Fernando Ferrari, Rua Anchieta, Rua Fernando Ferrari, Rua Dr. Beltrão, Av. Tupi, Av. Brasil, Rua Xingú, Rua Tamoio, P I 3, Rua Ararigbóia, Rua Tocantins, Rua Jaciretã, Av. Tupi, Trevo do Patinho, PR-493, Estrada Municipal, Vibra.
A17: SEGUNDA-FEIRA À SEXTA-FEIRA
A18: (Bairro Veneza) Rua Curitiba | B18: P I 2 Ponto Casa do Artesão (Rua Tamoio) | C18: Vibra
A19: 0.20486111 | B19: 0.21527778 | C19: 0.22916667
A21: Linha 206 - Centro Pq. Industrial 03 - Vibra
A22: Vibra, Estrada Municipal, PR-493, Trevo Patinho, Av. Tupi, Rua Tapir, Rua Caramuru, Rua Tamoio, P I 3.
A23: SEGUNDA-FEIRA À SEXTA-FEIRA
A24: Ponto Vibra | C24: PI 3 Antiga Rodoviária
A26: 0.66666667 | C26: 0.68055556
A27: 0.70833333 | C27: 0.72222222
A29: Linha 206 - Centro Pq. Industrial 03 - Vibra
A30: Rua Uruguaiana, (Supermercado Ponto Quente), Av. Tupi , Av. Brasil, Rua Xingú, Rua Tamoio, P I 3, Rua Ararigbóia, Rua Tocantins, Rua Jaciretã, Av. Tupi, Trevo do Patinho, PR-493, Estrada Municipal, Vibra.
A31: SEGUNDA-FEIRA À SEXTA-FEIRA
A32: P I 1 Ponto Casa do Artesão (Rua Caramuru) | B32: (Supermercado Ponto Quente) | C32: P I 2 Ponto Casa do Artesão (Rua Tamoio) | D32: Vibra
A33: 0.61805556 | B33: 0.625 | C33: 0.63194444 | D33: 0.64583333

Sheet 301 
A1: Linha 301 - Gralha Azul - Centro - Atlas
A2: P I 3, Rua Tamoio, Trevo da Taísa, BR-158, Atlas Eletrodomésticos, BR-158, Trevo Patinho, BR-158, Trevo Taísa, Rua Nereu Ramos, Rua Caramuru, P I 1, Rua Tamoio, Av. Tupi, Rua Uruguaiana, Rua Marechal Deodoro, Rua General Osório, Rua Tiradentes, Rua Princesa Isabel, Rua Jaury Heitor de Souza, (Bairro Gralha Azul), Rua Riciere Pastore, Rua Marcelino Parzianello, Rua Princesa Isabel, Av. Tupi, Av. Brasil, Rua Xingú, Rua Tamoio, P I 2.
A4: SEGUNDA-FEIRA À SEXTA-FEIRA
A5: P I 3 - Ponto Antiga Rodoviária (Rua Tamoio) | B5: Atlas Eletrodomésticos | C5: P I 1 - Ponto Casa do Artesão (Rua Caramuru) | D5: Bairro Gralha Azul
A6: 0.010416667 | B6: 0.03125 | C6: 0.045138889 | D6: 0.065972222
A7: 0.079861111 | B7: / | C7: / | D7: /
A9: P I 1, Rua Caramuru, Rua Tamoio, Av. Tupi, Marginal Av. Tupi, Rua das Flores, (Bairro Alvorada), Rua Jaury Heitor de Souza, (Bairro Gralha Azul), Rua Riciere Pastore, Rua Marcelino Parzianello, Rua Princesa Isabel, Av. Tupi, Bento Gonçalves, Rua das Hortências, Antônio Ascari, Rua Vicente Vieira Ferreira, Rua Fernando ferrari, Rua Dr. Beltrão, Av. Tupi, Av. Brasil, Rua Xingú, Rua Tamoio, P I 3, Rua Tamoio, Rua Farrapos, Av. Brasil, Trevo da Taísa, BR-158, ATLAS, BR-158, Trevo Taísa, Rua Nereu Ramos, Rua Caramuru, P I 2.
A10: SEGUNDA-FEIRA À SEXTA-FEIRA
A11: P I 1 - Ponto Casa do Artesão (Rua Caramuru) | B11: Bairro Gralha Azul | C11: P I 3 - Ponto Antiga Rodoviária (Rua Tamoio) | D11: Atlas Eletrodomésticos
A12: 0.17708333 | B12: 0.19097222 | C12: 0.20486111 | D12: 0.22569444
A13: 0.24652778 | B13: / | C13: / | D13: /
A15: P I 3, Rua Tamoio, Trevo da Taísa, BR-158, Atlas Eletrodomésticos, BR-158, Trevo Patinho, BR-158, Trevo Taísa, Rua Nereu Ramos, Rua Caramuru, P I 1, Rua Tamoio, Av. Tupi, Rua Dr. Beltrão, Rua Santa Fé, Rua Industrial, Rua Fernado Ferrari, Rua Anchieta, Rua Fernando Ferrari, Rua Angelo Dal Bosco, Rua das Violetas, Rua Curitiba, Rua General Osório, Rua Tiradentes, Rua Princesa Isabel, Rua Jaury Heitor de Souza, (Bairro Gralha Azul), Rua Riciere Pastore, Rua Marcelino Parzianello, Rua Princesa Isabel, Av. Tupi, Av. Brasil, Rua Xingú, Rua Tamoio, P I 2.
A17: SEGUNDA-FEIRA À SEXTA-FEIRA
A18: P I 3 - Ponto Antiga Rodoviária (Rua Tamoio) | B18: Atlas Eletrodomésticos | C18: P I 1 - Ponto Casa do Artesão (Rua Caramuru) | D18: Bairro Gralha Azul
B19: 0.73263889 | C19: 0.74652778 | D19: 0.76736111
A20: 0.78125 | B20: / | C20: / | D20: /
A22: P I 1, Rua Caramuru, Rua Tamoio, Av. Tupi, Marginal Av. Tupi, Rua das Flores, (Bairro Alvorada), Rua Jaury Heitor de Souza, (Bairro Gralha Azul), Rua Riciere Pastore, Rua Marcelino Parzianello, Rua Princesa Isabel, Rua Tiradentes, Rua General Osório, Rua Curitiba, Rua das Acácias, Rua Angelo Dal Bosco, Rua Fernando Ferrari, Rua Anchieta, Rua Fernando Ferrari, Rua Industrial, Rua Santa Fé, Rua Dr. Beltrão, Av. Tupi, Av. Brasil, Rua Xingú, Rua Tamoio, P I 3, Rua Tamoio, Trevo da Taísa, BR-158, Atlas Eletrodoméstico.
A24: SEGUNDA-FEIRA À SEXTA-FEIRA
A25: P I 1 - Ponto Casa do Artesão (Rua Caramuru) | B25: Bairro Gralha Azul | C25: P I 3 - Ponto Casa do Artesão (Rua Tamoio) | D25: Atlas Eletrodomésticos
